Workbook

Sheet Seed Methodology
B2: Seed methodology — how a pre-event strength value is derived
B3: Every method resolves to the same two fields the simulator consumes: a STRENGTH RANK within the field, and a CONFIDENCE grade. Confidence is separate from title volatility and does a different job — volatility says how much the title scrambles outcomes, confidence says how much we trust the seed. A weak seed widens the simulated spread even in a low-volatility title. Record also the snapshot date and whether the roster changed after it: a rating attaches to five players, not a logo.
B7: Method | C7: Conf. | D7: What it is | E7: When to use it | F7: Worked example | G7: Watch out for
B8: A · Actual seed / world rank | C8: A | D8: Published numeric ranking the ecosystem itself uses to invite or seed. | E8: First choice wherever it exists — gives ratings as well as ranks, so gaps are measurable. | F8: CS2 — Valve Regional Standings. Chess — FIDE / Chess.com rapid. | G8: Snapshot must predate the event; ratings attach to a roster.
B9: B · Most recent event / league form | C9: B | D9: Finishing order from a recent competition the same teams contested. | E9: Franchised or closed circuits where the field has just played each other. | F9: Black Ops 7 — CDL season standings. | G9: One event is a small sample; prefer a season table.
B10: C · Power ranking | C10: C | D10: Community or media composite ranking. | E10: Cross-region titles with no official ladder. | F10: PUBG, Dota 2 analyst tiering. | G10: Poor update cadence, opaque method. Record source and date.
B11: D · Cohort seeding (High/Med/Low) | C11: C | D11: Banded strength by region and international pedigree. | E11: Titles where regions rarely meet and ordinals would be false precision. | F11: LoL — LCK/LPL High; top LEC/AMER/PAC Med; rest Low. | G11: Sample WITHIN the band each run — never collapse a band to one rank.
B12: E · No credible seed | C12: D | D12: No usable pre-event signal exists. | E12: Declare it rather than forcing a proxy; simulator treats the field as flat. | F12: Warzone, Free Fire, Fortnite. | G12: Being explicit beats a fabricated seed that looks authoritative.
B14: PROPOSED METHOD PER TITLE — editable, for your approval
B15: Title | C15: TVI | D15: Method | E15: Proposed source | F15: Notes
B16: Counter-Strike 2 | C16: 52 | D16: A | E16: Valve Regional Standings (global snapshot) | F16: Ratings available — best-in-class source
B17: Chess | C17: 8 | D17: A | E17: FIDE / Chess.com rapid rating | F17: Elo is ideal simulator input
B18: Trackmania | C18: 22 | D18: A | E18: Elite Cup standings / TM world ranking
B19: Rocket League | C19: 26 | D19: B | E19: RLCS season standings
B20: Black Ops 7 | C20: 28 | D20: B | E20: CDL season standings | F20: Franchised — field has just played
B21: Rainbow Six Siege | C21: 30 | D21: B | E21: SI points / season standings
B22: Honor of Kings | C22: 32 | D22: B | E22: KPL season standings
B23: MLBB Women's | C23: 34 | D23: D | E23: Cohort: prior MWI final / ID-PH circuit High, knockout-pedigree regions Medium, expansion Low | F23: Proposed, needs approval — no cross-regional ranking exists
B24: Tekken 8 | C24: 36 | D24: C | E24: FGC / EWC ranking points
B25: CrossFire | C25: 38 | D25: B | E25: CFPL season standings
B26: League of Legends | C26: 40 | D26: D | E26: Cohort: LCK+LPL High / top LEC+AMER+PAC Med / rest Low | F26: Regions rarely meet
B27: Overwatch 2 | C27: 45 | D27: D | E27: Cohort: Korea S2 top 2 + NA/EMEA/China S2 winners High, Pacific + FACEIT Low, rest Medium | F27: Agreed rule
B28: Fatal Fury: CotW | C28: 45 | D28: C | E28: FGC circuit points | F28: Young title
B29: Valorant | C29: 50 | D29: D | E29: Cohort by region + VCT placement
B30: Dota 2 | C30: 55 | D30: C | E30: EPT standings
B31: Street Fighter 6 | C31: 58 | D31: C | E31: Capcom Pro Tour points
B32: MLBB (MSC) | C32: 60 | D32: B | E32: MPL regional standings
B33: PUBG | C33: 62 | D33: D | E33: Cohort: PGS Points seeds + title defender High, regional series seeds Medium | F33: PGS Points are global and comparable; regional PGC Points are not
B34: EA Sports FC 26 | C34: 65 | D34: C | E34: FC Pro rankings | F34: Weak predictor historically
B35: Teamfight Tactics | C35: 65 | D35: C | E35: TFT circuit points
B36: Free Fire | C36: 75 | D36: E | E36: — | F36: Regional fragmentation
B37: Warzone | C37: 75 | D37: E | E37: — | F37: Open qualification
B38: PUBG Mobile | C38: 78 | D38: C | E38: PMGC points
B39: Fortnite | C39: 80 | D39: E | E39: — | F39: Format changes yearly
B40: Apex Legends | C40: 82 | D40: C | E40: ALGS championship points | F40: Circuit points exist but weak predictor

Sheet Clubs
B2: Club registry — all Club Championship participants
B3: All 133 Club Championship-eligible clubs — i.e. every club that fielded more than one title at EWC26. Single-title clubs are excluded because they cannot score CC points. Every title tab joins on club_id.
B5: club_id | C5: Display name | D5: Aliases (semicolon separated) | E5: Titles fielded | F5: Qualified | G5: EWC26 CC points | H5: CC top 24
B6: team_falcons | C6: Team Falcons | D6: Riyadh Falcons; Falcons Vega; Falcons Vega MENA; Falcons Vega PH; Team Falcons PH | E6: 22 | F6: 22/25 | G6: 4600 | H6: Yes
B7: team_vitality | C7: Team Vitality | D7: Bigetron by Vitality; HavoK by Vitality; Bigetron MY by VIT | E7: 20 | F7: 17/25 | G7: 3300 | H7: Yes
B8: virtuspro | C8: Virtus.pro | D8: Virtus.pro Fe; Virtus.pro MENA | E8: 20 | F8: 13/25 | G8: 2200 | H8: Yes
B9: agal_international | C9: AG.AL International | D9: All Gamers; Anyone's Legend; AG Super Play; All Gamers Global | E9: 19 | F9: 18/25 | G9: 5300 | H9: Yes
B10: s8ul_esports | C10: S8UL Esports | D10: — | E10: 16 | F10: 6/25 | G10: 0
B11: twisted_minds | C11: Twisted Minds | D11: Twisted Minds ID; Twisted Minds VN; Twisted Minds PH; Twisted Minds Orchid | E11: 16 | F11: 9/25 | G11: 1900 | H11: Yes
B12: godlike | C12: GodLike | D12: — | E12: 15 | F12: 8/25 | G12: 0
B13: team_liquid | C13: Team Liquid | D13: Team Liquid ID; Team Liquid PH; Team Liquid Aqua | E13: 15 | F13: 10/25 | G13: 2700 | H13: Yes
B14: team_nemesis | C14: Team Nemesis | D14: — | E14: 15 | F14: 10/25 | G14: 0
B15: titan_esports_club | C15: Titan Esports Club | D15: — | E15: 15 | F15: 4/25 | G15: 0
B16: weibo_gaming | C16: Weibo Gaming | D16: — | E16: 15 | F16: 6/25 | G16: 1100 | H16: Yes
B17: ninjas_in_pyjamas | C17: Ninjas in Pyjamas | D17: — | E17: 14 | F17: 8/25 | G17: 0
B18: 9z_team | C18: 9z Team | D18: — | E18: 13 | F18: 2/25 | G18: 0
B19: aurora_gaming | C19: Aurora Gaming | D19: Aurora Avalanche; Aurora Storm; Aurora Gaming PH; Aurora Gaming (Serbia) | E19: 13 | F19: 11/25 | G19: 2150 | H19: Yes
B20: geng_esports | C20: Gen.G Esports | D20: — | E20: 13 | F20: 9/25 | G20: 0
B21: geekay_esports | C21: Geekay Esports | D21: — | E21: 12 | F21: 11/25 | G21: 0
B22: natus_vincere | C22: Natus Vincere | D22: Natus Vincere PH; Natus Vincere MY | E22: 12 | F22: 7/25 | G22: 2950 | H22: Yes
B23: the_vicious | C23: The Vicious | D23: — | E23: 12 | F23: 4/25 | G23: 0
B24: fnatic | C24: Fnatic | D24: — | E24: 11 | F24: 6/25 | G24: 0
B25: t1 | C25: T1 | D25: — | E25: 11 | F25: 7/25 | G25: 1800 | H25: Yes
B26: team_spirit | C26: Team Spirit | D26: — | E26: 11 | F26: 3/25 | G26: 2200 | H26: Yes
B27: team_vision | C27: Team Vision | D27: Vision Esports | E27: 11 | F27: 2/25 | G27: 1750 | H27: Yes
B28: furia | C28: FURIA | D28: FURIA Esports | E28: 10 | F28: 6/25 | G28: 1050 | H28: Yes
B29: fut_esports | C29: FUT Esports | D29: — | E29: 10 | F29: 5/25 | G29: 0
B30: rex_regum_qeon | C30: Rex Regum Qeon | D30: — | E30: 10 | F30: 5/25 | G30: 0
B31: team_spirit | C31: Team Spirit | D31: — | E31: 10 | F31: 4/25 | G31: 2200 | H31: Yes
B32: jd_gaming | C32: JD Gaming | D32: — | E32: 9 | F32: 6/25 | G32: 0
B33: leviatán | C33: Leviatán | D33: — | E33: 9 | F33: 4/25 | G33: 0
B34: onic | C34: ONIC | D34: — | E34: 9 | F34: 5/25 | G34: 0
B35: reject | C35: REJECT | D35: — | E35: 9 | F35: 5/25 | G35: 1000 | H35: Yes
B36: team_heretics | C36: Team Heretics | D36: Miami Heretics | E36: 9 | F36: 6/25 | G36: 950 | H36: Yes
B37: edward_gaming | C37: EDward Gaming | D37: — | E37: 8 | F37: 2/25 | G37: 0
B38: mibrlos | C38: MIBR.LOS | D38: — | E38: 8 | F38: 8/25 | G38: 0
B39: roc_esports | C39: ROC Esports | D39: — | E39: 8 | F39: 4/25 | G39: 0
B40: wolves_esports | C40: Wolves Esports | D40: — | E40: 8 | F40: 2/25 | G40: 0
B41: zeta_division | C41: ZETA DIVISION | D41: — | E41: 8 | F41: 5/25 | G41: 1500 | H41: Yes
B42: drx | C42: DRX | D42: — | E42: 7 | F42: 3/25 | G42: 950 | H42: Yes
...

Sheet CS2
B2: Counter-Strike 2 — EWC 2026
B3: TEMPLATE TAB — copy this sheet for every new title. Three stacked blocks: 1) field & results, 2) point system, 3) seed reference. All CS2 data below is VERIFIED against liquipedia.net/counterstrike/Esports_World_Cup/2026.
B5: FORMAT | D5: FIELD SIZE | F5: TVI | H5: SEED METHOD | J5: SEED SOURCE | L5: PLACEMENT GRANULARITY
B6: 4× GSL groups → 16-team single-elim | D6: 32 (confirmed) | F6: 52 · Medium | H6: A — world rank | J6: Valve VRS global, 3 Aug 2026 (latest pre-event) | L6: Bands (5-8, 9-16, 17-32 share points)
B8: 1 · FIELD & RESULTS
B9: Complete 32-team field, sorted by finishing position. Placements and point table taken from the Liquipedia event page; seeds from Valve's latest pre-event VRS (3 Aug 2026), which reflects form better than the June invite snapshot. June ranks retained in block 3 for reference. Points auto-calculate from block 2 and are checked against official CC points.
B10: Club | C10: Seed (VRS Aug) | D10: Group | E10: Placement | F10: Points (auto) | G10: Official CC pts | H10: Δ check | I10: Prize (USD) | J10: Notes | L10: Club (canonical)
B11: Team Spirit | C11: 1 | D11: A | E11: 1 | F11: =IF($E11="","",IFERROR(LOOKUP(VALUE(LEFT($E11&"",FIND("-",$E11&"-")-1)),$C$54:$C$59,$D$54:$D$59),"")) -> 1000 | G11: 1000 | H11: =IF($G11="","n/a",IF($F11=$G11,"ok","MISMATCH")) -> ok | I11: 600000 | L11: Team Spirit
B12: FUT Esports | C12: 14 | D12: C | E12: 2 | F12: =IF($E12="","",IFERROR(LOOKUP(VALUE(LEFT($E12&"",FIND("-",$E12&"-")-1)),$C$54:$C$59,$D$54:$D$59),"")) -> 750 | G12: 750 | H12: =IF($G12="","n/a",IF($F12=$G12,"ok","MISMATCH")) -> ok | I12: 340000 | L12: FUT Esports
B13: Legacy | C13: 7 | D13: B | E13: 3 | F13: =IF($E13="","",IFERROR(LOOKUP(VALUE(LEFT($E13&"",FIND("-",$E13&"-")-1)),$C$54:$C$59,$D$54:$D$59),"")) -> 500 | G13: 500 | H13: =IF($G13="","n/a",IF($F13=$G13,"ok","MISMATCH")) -> ok | I13: 190000 | L13: Legacy
B14: FURIA | C14: 8 | D14: D | E14: 4 | F14: =IF($E14="","",IFERROR(LOOKUP(VALUE(LEFT($E14&"",FIND("-",$E14&"-")-1)),$C$54:$C$59,$D$54:$D$59),"")) -> 300 | G14: 300 | H14: =IF($G14="","n/a",IF($F14=$G14,"ok","MISMATCH")) -> ok | I14: 110000 | L14: FURIA
B15: G2 Esports | C15: 11 | D15: A | E15: 5-8 | F15: =IF($E15="","",IFERROR(LOOKUP(VALUE(LEFT($E15&"",FIND("-",$E15&"-")-1)),$C$54:$C$59,$D$54:$D$59),"")) -> 200 | G15: 200 | H15: =IF($G15="","n/a",IF($F15=$G15,"ok","MISMATCH")) -> ok | I15: 60000 | L15: G2 Esports
B16: MOUZ | C16: 3 | D16: C | E16: 5-8 | F16: =IF($E16="","",IFERROR(LOOKUP(VALUE(LEFT($E16&"",FIND("-",$E16&"-")-1)),$C$54:$C$59,$D$54:$D$59),"")) -> 200 | G16: 200 | H16: =IF($G16="","n/a",IF($F16=$G16,"ok","MISMATCH")) -> ok | I16: 60000 | L16: MOUZ
B17: Team Falcons | C17: 2 | D17: B | E17: 5-8 | F17: =IF($E17="","",IFERROR(LOOKUP(VALUE(LEFT($E17&"",FIND("-",$E17&"-")-1)),$C$54:$C$59,$D$54:$D$59),"")) -> 200 | G17: 200 | H17: =IF($G17="","n/a",IF($F17=$G17,"ok","MISMATCH")) -> ok | I17: 60000 | L17: Team Falcons
B18: Team Vitality | C18: 5 | D18: C | E18: 5-8 | F18: =IF($E18="","",IFERROR(LOOKUP(VALUE(LEFT($E18&"",FIND("-",$E18&"-")-1)),$C$54:$C$59,$D$54:$D$59),"")) -> 200 | G18: 200 | H18: =IF($G18="","n/a",IF($F18=$G18,"ok","MISMATCH")) -> ok | I18: 60000 | L18: Team Vitality
B19: GamerLegion | C19: 22 | D19: A | E19: 9-16 | F19: =IF($E19="","",IFERROR(LOOKUP(VALUE(LEFT($E19&"",FIND("-",$E19&"-")-1)),$C$54:$C$59,$D$54:$D$59),"")) -> 0 | H19: =IF($G19="","n/a",IF($F19=$G19,"ok","MISMATCH")) -> n/a | J19: moved 9→22 between June invite list and event | L19: GamerLegion
B20: Aurora Gaming | C20: 10 | D20: A | E20: 9-16 | F20: =IF($E20="","",IFERROR(LOOKUP(VALUE(LEFT($E20&"",FIND("-",$E20&"-")-1)),$C$54:$C$59,$D$54:$D$59),"")) -> 0 | G20: 0 | H20: =IF($G20="","n/a",IF($F20=$G20,"ok","MISMATCH")) -> ok | L20: Aurora Gaming
B21: FaZe Clan | C21: 13 | D21: B | E21: 9-16 | F21: =IF($E21="","",IFERROR(LOOKUP(VALUE(LEFT($E21&"",FIND("-",$E21&"-")-1)),$C$54:$C$59,$D$54:$D$59),"")) -> 0 | G21: 0 | H21: =IF($G21="","n/a",IF($F21=$G21,"ok","MISMATCH")) -> ok | J21: moved 22→13 between June invite list and event | L21: FaZe Clan
B22: Astralis | C22: 19 | D22: B | E22: 9-16 | F22: =IF($E22="","",IFERROR(LOOKUP(VALUE(LEFT($E22&"",FIND("-",$E22&"-")-1)),$C$54:$C$59,$D$54:$D$59),"")) -> 0 | H22: =IF($G22="","n/a",IF($F22=$G22,"ok","MISMATCH")) -> n/a | J22: moved 10→19 between June invite list and event | L22: Astralis
B23: B8 | C23: 20 | D23: C | E23: 9-16 | F23: =IF($E23="","",IFERROR(LOOKUP(VALUE(LEFT($E23&"",FIND("-",$E23&"-")-1)),$C$54:$C$59,$D$54:$D$59),"")) -> 0 | H23: =IF($G23="","n/a",IF($F23=$G23,"ok","MISMATCH")) -> n/a | L23: B8
B24: Natus Vincere | C24: 6 | D24: D | E24: 9-16 | F24: =IF($E24="","",IFERROR(LOOKUP(VALUE(LEFT($E24&"",FIND("-",$E24&"-")-1)),$C$54:$C$59,$D$54:$D$59),"")) -> 0 | G24: 0 | H24: =IF($G24="","n/a",IF($F24=$G24,"ok","MISMATCH")) -> ok | L24: Natus Vincere
B25: magic | C25: 23 | D25: D | E25: 9-16 | F25: =IF($E25="","",IFERROR(LOOKUP(VALUE(LEFT($E25&"",FIND("-",$E25&"-")-1)),$C$54:$C$59,$D$54:$D$59),"")) -> 0 | H25: =IF($G25="","n/a",IF($F25=$G25,"ok","MISMATCH")) -> n/a | L25: magic
B26: The MongolZ | C26: 15 | D26: D | E26: 9-16 | F26: =IF($E26="","",IFERROR(LOOKUP(VALUE(LEFT($E26&"",FIND("-",$E26&"-")-1)),$C$54:$C$59,$D$54:$D$59),"")) -> 0 | H26: =IF($G26="","n/a",IF($F26=$G26,"ok","MISMATCH")) -> n/a | J26: moved 7→15 between June invite list and event | L26: The MongolZ
B27: JiJieHao | C27: 58 | D27: A | E27: 17-32 | F27: =IF($E27="","",IFERROR(LOOKUP(VALUE(LEFT($E27&"",FIND("-",$E27&"-")-1)),$C$54:$C$59,$D$54:$D$59),"")) -> 0 | H27: =IF($G27="","n/a",IF($F27=$G27,"ok","MISMATCH")) -> n/a | J27: moved 44→58 between June invite list and event | L27: JiJieHao
B28: Luminosity | C28: 24 | D28: A | E28: 17-32 | F28: =IF($E28="","",IFERROR(LOOKUP(VALUE(LEFT($E28&"",FIND("-",$E28&"-")-1)),$C$54:$C$59,$D$54:$D$59),"")) -> 0 | H28: =IF($G28="","n/a",IF($F28=$G28,"ok","MISMATCH")) -> n/a | J28: no June VRS entry — returned to CS2 in July 2026 | L28: Luminosity
B29: M80 | C29: 36 | D29: A | E29: 17-32 | F29: =IF($E29="","",IFERROR(LOOKUP(VALUE(LEFT($E29&"",FIND("-",$E29&"-")-1)),$C$54:$C$59,$D$54:$D$59),"")) -> 0 | H29: =IF($G29="","n/a",IF($F29=$G29,"ok","MISMATCH")) -> n/a | L29: M80
B30: BIG | C30: 21 | D30: A | E30: 17-32 | F30: =IF($E30="","",IFERROR(LOOKUP(VALUE(LEFT($E30&"",FIND("-",$E30&"-")-1)),$C$54:$C$59,$D$54:$D$59),"")) -> 0 | G30: 0 | H30: =IF($G30="","n/a",IF($F30=$G30,"ok","MISMATCH")) -> ok | J30: moved 28→21 between June invite list and event | L30: BIG
B31: K27 | C31: 39 | D31: B | E31: 17-32 | F31: =IF($E31="","",IFERROR(LOOKUP(VALUE(LEFT($E31&"",FIND("-",$E31&"-")-1)),$C$54:$C$59,$D$54:$D$59),"")) -> 0 | H31: =IF($G31="","n/a",IF($F31=$G31,"ok","MISMATCH")) -> n/a | L31: K27
B32: MIBR | C32: 16 | D32: B | E32: 17-32 | F32: =IF($E32="","",IFERROR(LOOKUP(VALUE(LEFT($E32&"",FIND("-",$E32&"-")-1)),$C$54:$C$59,$D$54:$D$59),"")) -> 0 | H32: =IF($G32="","n/a",IF($F32=$G32,"ok","MISMATCH")) -> n/a | L32: MIBR.LOS
B33: BetBoom | C33: 9 | D33: B | E33: 17-32 | F33: =IF($E33="","",IFERROR(LOOKUP(VALUE(LEFT($E33&"",FIND("-",$E33&"-")-1)),$C$54:$C$59,$D$54:$D$59),"")) -> 0 | H33: =IF($G33="","n/a",IF($F33=$G33,"ok","MISMATCH")) -> n/a | J33: moved 17→9 between June invite list and event | L33: BetBoom
B34: Ninjas in Pyjamas | C34: 27 | D34: B | E34: 17-32 | F34: =IF($E34="","",IFERROR(LOOKUP(VALUE(LEFT($E34&"",FIND("-",$E34&"-")-1)),$C$54:$C$59,$D$54:$D$59),"")) -> 0 | G34: 0 | H34: =IF($G34="","n/a",IF($F34=$G34,"ok","MISMATCH")) -> ok | L34: Ninjas in Pyjamas
B35: 100 Thieves | C35: 40 | D35: C | E35: 17-32 | F35: =IF($E35="","",IFERROR(LOOKUP(VALUE(LEFT($E35&"",FIND("-",$E35&"-")-1)),$C$54:$C$59,$D$54:$D$59),"")) -> 0 | G35: 0 | H35: =IF($G35="","n/a",IF($F35=$G35,"ok","MISMATCH")) -> ok | J35: moved 47→40 between June invite list and event | L35: 100 Thieves
B36: PARIVISION | C36: 12 | D36: C | E36: 17-32 | F36: =IF($E36="","",IFERROR(LOOKUP(VALUE(LEFT($E36&"",FIND("-",$E36&"-")-1)),$C$54:$C$59,$D$54:$D$59),"")) -> 0 | G36: 0 | H36: =IF($G36="","n/a",IF($F36=$G36,"ok","MISMATCH")) -> ok | L36: PARIVISION
B37: TYLOO | C37: 18 | D37: C | E37: 17-32 | F37: =IF($E37="","",IFERROR(LOOKUP(VALUE(LEFT($E37&"",FIND("-",$E37&"-")-1)),$C$54:$C$59,$D$54:$D$59),"")) -> 0 | H37: =IF($G37="","n/a",IF($F37=$G37,"ok","MISMATCH")) -> n/a | J37: moved 32→18 between June invite list and event | L37: TYLOO
B38: Lynn Vision | C38: 29 | D38: C | E38: 17-32 | F38: =IF($E38="","",IFERROR(LOOKUP(VALUE(LEFT($E38&"",FIND("-",$E38&"-")-1)),$C$54:$C$59,$D$54:$D$59),"")) -> 0 | H38: =IF($G38="","n/a",IF($F38=$G38,"ok","MISMATCH")) -> n/a | L38: Lynn Vision
B39: 3DMAX | C39: 31 | D39: D | E39: 17-32 | F39: =IF($E39="","",IFERROR(LOOKUP(VALUE(LEFT($E39&"",FIND("-",$E39&"-")-1)),$C$54:$C$59,$D$54:$D$59),"")) -> 0 | H39: =IF($G39="","n/a",IF($F39=$G39,"ok","MISMATCH")) -> n/a | L39: 3DMAX
B40: 9z | C40: 4 | D40: D | E40: 17-32 | F40: =IF($E40="","",IFERROR(LOOKUP(VALUE(LEFT($E40&"",FIND("-",$E40&"-")-1)),$C$54:$C$59,$D$54:$D$59),"")) -> 0 | H40: =IF($G40="","n/a",IF($F40=$G40,"ok","MISMATCH")) -> n/a | J40: moved 15→4 between June invite list and event | L40: 9z Team
B41: paiN | C41: 26 | D41: D | E41: 17-32 | F41: =IF($E41="","",IFERROR(LOOKUP(VALUE(LEFT($E41&"",FIND("-",$E41&"-")-1)),$C$54:$C$59,$D$54:$D$59),"")) -> 0 | H41: =IF($G41="","n/a",IF($F41=$G41,"ok","MISMATCH")) -> n/a | J41: moved 19→26 between June invite list and event | L41: paiN
B42: Wildcard | C42: 38 | D42: D | E42: 17-32 | F42: =IF($E42="","",IFERROR(LOOKUP(VALUE(LEFT($E42&"",FIND("-",$E42&"-")-1)),$C$54:$C$59,$D$54:$D$59),"")) -> 0 | G42: 0 | H42: =IF($G42="","n/a",IF($F42=$G42,"ok","MISMATCH")) -> ok | J42: moved 25→38 between June invite list and event | L42: Wildcard
B44: TOTAL POINTS AWARDED | F44: =SUM(F11:F42) -> 3350
...

Sheet Chess
B2: Chess — EWC 2026
B3: Built on the CS2 template. Verified against liquipedia.net/chess/Esports_World_Cup/2026. Individual title: rows are PLAYERS, points accrue to their club.
B5: FORMAT | D5: FIELD SIZE | F5: TVI | H5: SEED METHOD | J5: SEED SOURCE | L5: PLACEMENT GRANULARITY
B6: Play-ins(8) → 2× groups of 8 → 8-player single-elim | D6: 22 players | F6: 8 · Low | H6: A — world rank | J6: FIDE rapid rating, August 2026 list | L6: Bands (5-8, 9-22 share points)
B8: 1 · FIELD & RESULTS
B9: All 22 players with exact placements from the Liquipedia prize table and seeds derived from the FIDE rapid rating list for August 2026 — a genuine pre-event snapshot, since EWC chess ran 11-15 August.
B10: Club | C10: Player | D10: Seed (rapid rank) | E10: Placement | F10: Points (auto) | G10: Official CC pts | H10: Δ check | I10: Prize (USD) | J10: Qualification route | L10: Club (canonical)
B11: Team Liquid | C11: Magnus Carlsen | D11: 1 | E11: 1 | F11: =IF($E11="","",IFERROR(LOOKUP(VALUE(LEFT($E11&"",FIND("-",$E11&"-")-1)),$C$44:$C$49,$D$44:$D$49),"")) -> 1000 | G11: 1000 | H11: =IF($G11="","n/a",IF($F11=$G11,"ok","MISMATCH")) -> ok | I11: 250000 | J11: EWC 2025 Champion | L11: Team Liquid
B12: AG.AL International | C12: Denis Lazavik | D12: 17 | E12: 2 | F12: =IF($E12="","",IFERROR(LOOKUP(VALUE(LEFT($E12&"",FIND("-",$E12&"-")-1)),$C$44:$C$49,$D$44:$D$49),"")) -> 750 | G12: 750 | H12: =IF($G12="","n/a",IF($F12=$G12,"ok","MISMATCH")) -> ok | I12: 190000 | J12: SCC 2025 / CCT points | L12: AG.AL International
B13: Team Falcons | C13: Hikaru Nakamura | D13: 4 | E13: 3 | F13: =IF($E13="","",IFERROR(LOOKUP(VALUE(LEFT($E13&"",FIND("-",$E13&"-")-1)),$C$44:$C$49,$D$44:$D$49),"")) -> 500 | G13: 500 | H13: =IF($G13="","n/a",IF($F13=$G13,"ok","MISMATCH")) -> ok | I13: 145000 | J13: CCT 2025-26 Circuit Points | L13: Team Falcons
B14: Team Falcons | C14: Alireza Firouzja | D14: 2 | E14: 4 | F14: =IF($E14="","",IFERROR(LOOKUP(VALUE(LEFT($E14&"",FIND("-",$E14&"-")-1)),$C$44:$C$49,$D$44:$D$49),"")) -> 300 | H14: =IF($G14="","n/a",IF($F14=$G14,"ok","MISMATCH")) -> n/a | I14: 100000 | J14: SCC 2025 | L14: Team Falcons
B15: S8UL Esports | C15: Nihal Sarin | D15: 9 | E15: 5-8 | F15: =IF($E15="","",IFERROR(LOOKUP(VALUE(LEFT($E15&"",FIND("-",$E15&"-")-1)),$C$44:$C$49,$D$44:$D$49),"")) -> 200 | G15: 200 | H15: =IF($G15="","n/a",IF($F15=$G15,"ok","MISMATCH")) -> ok | I15: 72500 | J15: CCT 2025-26 Circuit Points | L15: S8UL Esports
B16: GodLike Esports | C16: Hans Moke Niemann | D16: 12 | E16: 5-8 | F16: =IF($E16="","",IFERROR(LOOKUP(VALUE(LEFT($E16&"",FIND("-",$E16&"-")-1)),$C$44:$C$49,$D$44:$D$49),"")) -> 200 | H16: =IF($G16="","n/a",IF($F16=$G16,"ok","MISMATCH")) -> n/a | I16: 72500 | J16: CCT 2025-26 Circuit Points | L16: GodLike
B17: Natus Vincere | C17: Nodirbek Abdusattorov | D17: 8 | E17: 5-8 | F17: =IF($E17="","",IFERROR(LOOKUP(VALUE(LEFT($E17&"",FIND("-",$E17&"-")-1)),$C$44:$C$49,$D$44:$D$49),"")) -> 200 | G17: 200 | H17: =IF($G17="","n/a",IF($F17=$G17,"ok","MISMATCH")) -> ok | I17: 72500 | J17: CCT 2025-26 Circuit Points | L17: Natus Vincere
B18: Gen.G Esports | C18: Arjun Erigaisi | D18: 3 | E18: 5-8 | F18: =IF($E18="","",IFERROR(LOOKUP(VALUE(LEFT($E18&"",FIND("-",$E18&"-")-1)),$C$44:$C$49,$D$44:$D$49),"")) -> 200 | G18: 200 | H18: =IF($G18="","n/a",IF($F18=$G18,"ok","MISMATCH")) -> ok | I18: 72500 | J18: CCT points (replacement for Caruana) | L18: Gen.G Esports
B19: Weibo Gaming | C19: Jan-Krzysztof Duda | D19: 11 | E19: 9-12 | F19: =IF($E19="","",IFERROR(LOOKUP(VALUE(LEFT($E19&"",FIND("-",$E19&"-")-1)),$C$44:$C$49,$D$44:$D$49),"")) -> 0 | G19: 0 | H19: =IF($G19="","n/a",IF($F19=$G19,"ok","MISMATCH")) -> ok | I19: 52500 | J19: Chess.com Open 2026 | L19: Weibo Gaming
B20: S8UL Esports | C20: Pranesh M | D20: 21 | E20: 9-12 | F20: =IF($E20="","",IFERROR(LOOKUP(VALUE(LEFT($E20&"",FIND("-",$E20&"-")-1)),$C$44:$C$49,$D$44:$D$49),"")) -> 0 | H20: =IF($G20="","n/a",IF($F20=$G20,"ok","MISMATCH")) -> n/a | I20: 52500 | J20: CCT points (replacement for MVL) | L20: S8UL Esports
B21: Aurora Gaming | C21: Ian Nepomniachtchi | D21: 5 | E21: 9-12 | F21: =IF($E21="","",IFERROR(LOOKUP(VALUE(LEFT($E21&"",FIND("-",$E21&"-")-1)),$C$44:$C$49,$D$44:$D$49),"")) -> 0 | G21: 0 | H21: =IF($G21="","n/a",IF($F21=$G21,"ok","MISMATCH")) -> ok | I21: 52500 | J21: CCT 2025-26 Circuit Points | L21: Aurora Gaming
B22: Team Stallions | C22: Sina Movahed | D22: 22 | E22: 9-12 | F22: =IF($E22="","",IFERROR(LOOKUP(VALUE(LEFT($E22&"",FIND("-",$E22&"-")-1)),$C$44:$C$49,$D$44:$D$49),"")) -> 0 | G22: 0 | H22: =IF($G22="","n/a",IF($F22=$G22,"ok","MISMATCH")) -> ok | I22: 52500 | J22: CCT 2025-26 Circuit Points | L22: Team Stallions
B23: Team Nemesis | C23: Wei Yi | D23: 6 | E23: 13-16 | F23: =IF($E23="","",IFERROR(LOOKUP(VALUE(LEFT($E23&"",FIND("-",$E23&"-")-1)),$C$44:$C$49,$D$44:$D$49),"")) -> 0 | G23: 0 | H23: =IF($G23="","n/a",IF($F23=$G23,"ok","MISMATCH")) -> ok | I23: 40000 | J23: Last Chance Qualifier | L23: Team Nemesis
B24: Team MGD1 | C24: Benjamin Bok | D24: 20 | E24: 13-16 | F24: =IF($E24="","",IFERROR(LOOKUP(VALUE(LEFT($E24&"",FIND("-",$E24&"-")-1)),$C$44:$C$49,$D$44:$D$49),"")) -> 0 | H24: =IF($G24="","n/a",IF($F24=$G24,"ok","MISMATCH")) -> n/a | I24: 40000 | J24: India Rising 2026 | L24: Team MGD1
B25: Virtus.pro | C25: Andrey Esipenko | D25: 14 | E25: 13-16 | F25: =IF($E25="","",IFERROR(LOOKUP(VALUE(LEFT($E25&"",FIND("-",$E25&"-")-1)),$C$44:$C$49,$D$44:$D$49),"")) -> 0 | G25: 0 | H25: =IF($G25="","n/a",IF($F25=$G25,"ok","MISMATCH")) -> ok | I25: 40000 | J25: DH Atlanta | L25: Virtus.pro
B26: Fnatic | C26: Alexey Sarana | D26: 15 | E26: 13-16 | F26: =IF($E26="","",IFERROR(LOOKUP(VALUE(LEFT($E26&"",FIND("-",$E26&"-")-1)),$C$44:$C$49,$D$44:$D$49),"")) -> 0 | G26: 0 | H26: =IF($G26="","n/a",IF($F26=$G26,"ok","MISMATCH")) -> ok | I26: 40000 | J26: DH Atlanta / higher seed via CCT | L26: Fnatic
B27: Team Spirit | C27: Vladislav Artemiev | D27: 7 | E27: 17 | F27: =IF($E27="","",IFERROR(LOOKUP(VALUE(LEFT($E27&"",FIND("-",$E27&"-")-1)),$C$44:$C$49,$D$44:$D$49),"")) -> 0 | G27: 0 | H27: =IF($G27="","n/a",IF($F27=$G27,"ok","MISMATCH")) -> ok | I27: 32000 | J27: Last Chance Qualifier | L27: Team Spirit
B28: (no club) | C28: Parham Maghsoodloo | D28: 10 | E28: 18 | F28: =IF($E28="","",IFERROR(LOOKUP(VALUE(LEFT($E28&"",FIND("-",$E28&"-")-1)),$C$44:$C$49,$D$44:$D$49),"")) -> 0 | H28: =IF($G28="","n/a",IF($F28=$G28,"ok","MISMATCH")) -> n/a | I28: 27000 | J28: Last Chance Qualifier | L28: (no club)
B29: (no club) | C29: Olexandr Bortnyk | D29: 18 | E29: 19-20 | F29: =IF($E29="","",IFERROR(LOOKUP(VALUE(LEFT($E29&"",FIND("-",$E29&"-")-1)),$C$44:$C$49,$D$44:$D$49),"")) -> 0 | H29: =IF($G29="","n/a",IF($F29=$G29,"ok","MISMATCH")) -> n/a | I29: 25000 | J29: Last Chance Qualifier | L29: (no club)
B30: (no club) | C30: Alexander Grischuk | D30: 13 | E30: 19-20 | F30: =IF($E30="","",IFERROR(LOOKUP(VALUE(LEFT($E30&"",FIND("-",$E30&"-")-1)),$C$44:$C$49,$D$44:$D$49),"")) -> 0 | H30: =IF($G30="","n/a",IF($F30=$G30,"ok","MISMATCH")) -> n/a | I30: 25000 | J30: Last Chance Qualifier | L30: (no club)
B31: S8UL Esports | C31: Aravindh Chithambaram | D31: 19 | E31: 21-22 | F31: =IF($E31="","",IFERROR(LOOKUP(VALUE(LEFT($E31&"",FIND("-",$E31&"-")-1)),$C$44:$C$49,$D$44:$D$49),"")) -> 0 | H31: =IF($G31="","n/a",IF($F31=$G31,"ok","MISMATCH")) -> n/a | I31: 23000 | J31: DH Atlanta | L31: S8UL Esports
B32: Team Flash | C32: Lê Quang Liêm | D32: 16 | E32: 21-22 | F32: =IF($E32="","",IFERROR(LOOKUP(VALUE(LEFT($E32&"",FIND("-",$E32&"-")-1)),$C$44:$C$49,$D$44:$D$49),"")) -> 0 | H32: =IF($G32="","n/a",IF($F32=$G32,"ok","MISMATCH")) -> n/a | I32: 23000 | J32: DH Atlanta | L32: Team Flash
B34: TOTAL POINTS AWARDED | F34: =SUM(F11:F32) -> 3350
B35: 1000+750+500+300+(200×4) = 3,350 awarded to players. Club totals differ: a club scores only its BEST placement per title — Falcons had both Nakamura (3rd) and Firouzja (4th) but scored 500, not 800.
B41: 2 · POINT SYSTEM
B42: Read directly from the Liquipedia prize-pool table, which lists club points and prize money for every placement band down to 21st–22nd. Club points stop after 8th; prize money continues to 22nd (all $1.5M accounted for).
B43: From place | C43: Club points | D43: Band
C44: 1 | D44: 1000 | E44: 1st
C45: 2 | D45: 750 | E45: 2nd
C46: 3 | D46: 500 | E46: 3rd
C47: 4 | D47: 300 | E47: 4th
C48: 5 | D48: 200 | E48: 5th-8th
C49: 9 | D49: 0 | E49: 9th-22nd (prize money only)
...

Sheet LoL
B2: League of Legends — EWC 2026
B3: Cohort-seeded title. Regions and cohorts below are SUGGESTIONS — the Liquipedia page carries no participant/region table, so confirm both. Cohort is a dropdown; the model in block 4 turns it into simulator inputs.
B5: FORMAT | D5: FIELD SIZE | F5: TVI | H5: SEED METHOD | J5: SEED SOURCE | L5: PLACEMENT GRANULARITY
B6: 4 groups → playoffs | D6: 16 teams | F6: 40 · Low | H6: D — cohort seeding | J6: Manual: region + international pedigree | L6: Bands (5-8, 9-12, 13-16)
B8: 1 · FIELD & RESULTS
B9: All 16 teams with exact placement bands and prize money from the Liquipedia prize table. Cohort drives the simulator — edit it directly.
B10: Club | C10: Region | D10: Cohort | E10: Placement | F10: Points (auto) | G10: Official CC pts | H10: Δ check | I10: Prize (USD) | J10: Notes | L10: Club (canonical)
B11: Dplus | C11: LCK | D11: High | E11: 1 | F11: =IF($E11="","",IFERROR(LOOKUP(VALUE(LEFT($E11&"",FIND("-",$E11&"-")-1)),$C$34:$C$39,$D$34:$D$39),"")) -> 1000 | H11: =IF($G11="","n/a",IF($F11=$G11,"ok","MISMATCH")) -> n/a | I11: 600000 | L11: Dplus
B12: Karmine Corp | C12: LEC | D12: Medium | E12: 2 | F12: =IF($E12="","",IFERROR(LOOKUP(VALUE(LEFT($E12&"",FIND("-",$E12&"-")-1)),$C$34:$C$39,$D$34:$D$39),"")) -> 750 | G12: 750 | H12: =IF($G12="","n/a",IF($F12=$G12,"ok","MISMATCH")) -> ok | I12: 340000 | L12: Karmine Corp
B13: Gen.G Esports | C13: LCK | D13: High | E13: 3 | F13: =IF($E13="","",IFERROR(LOOKUP(VALUE(LEFT($E13&"",FIND("-",$E13&"-")-1)),$C$34:$C$39,$D$34:$D$39),"")) -> 500 | G13: 500 | H13: =IF($G13="","n/a",IF($F13=$G13,"ok","MISMATCH")) -> ok | I13: 220000 | L13: Gen.G Esports
B14: T1 | C14: LCK | D14: High | E14: 4 | F14: =IF($E14="","",IFERROR(LOOKUP(VALUE(LEFT($E14&"",FIND("-",$E14&"-")-1)),$C$34:$C$39,$D$34:$D$39),"")) -> 300 | G14: 300 | H14: =IF($G14="","n/a",IF($F14=$G14,"ok","MISMATCH")) -> ok | I14: 140000 | L14: T1
B15: Hanwha Life Esports | C15: LCK | D15: High | E15: 5-8 | F15: =IF($E15="","",IFERROR(LOOKUP(VALUE(LEFT($E15&"",FIND("-",$E15&"-")-1)),$C$34:$C$39,$D$34:$D$39),"")) -> 200 | G15: 200 | H15: =IF($G15="","n/a",IF($F15=$G15,"ok","MISMATCH")) -> ok | I15: 90000 | L15: Hanwha Life Esports
B16: AG.AL International | C16: LPL | D16: High | E16: 5-8 | F16: =IF($E16="","",IFERROR(LOOKUP(VALUE(LEFT($E16&"",FIND("-",$E16&"-")-1)),$C$34:$C$39,$D$34:$D$39),"")) -> 200 | G16: 200 | H16: =IF($G16="","n/a",IF($F16=$G16,"ok","MISMATCH")) -> ok | I16: 90000 | L16: AG.AL International
B17: JD Gaming | C17: LPL | D17: High | E17: 5-8 | F17: =IF($E17="","",IFERROR(LOOKUP(VALUE(LEFT($E17&"",FIND("-",$E17&"-")-1)),$C$34:$C$39,$D$34:$D$39),"")) -> 200 | G17: 200 | H17: =IF($G17="","n/a",IF($F17=$G17,"ok","MISMATCH")) -> ok | I17: 90000 | L17: JD Gaming
B18: Bilibili Gaming | C18: LPL | D18: High | E18: 5-8 | F18: =IF($E18="","",IFERROR(LOOKUP(VALUE(LEFT($E18&"",FIND("-",$E18&"-")-1)),$C$34:$C$39,$D$34:$D$39),"")) -> 200 | G18: 200 | H18: =IF($G18="","n/a",IF($F18=$G18,"ok","MISMATCH")) -> ok | I18: 90000 | L18: Bilibili Gaming
B19: G2 Esports | C19: LEC | D19: Medium | E19: 9-12 | F19: =IF($E19="","",IFERROR(LOOKUP(VALUE(LEFT($E19&"",FIND("-",$E19&"-")-1)),$C$34:$C$39,$D$34:$D$39),"")) -> 0 | G19: 0 | H19: =IF($G19="","n/a",IF($F19=$G19,"ok","MISMATCH")) -> ok | I19: 55000 | L19: G2 Esports
B20: Sentinels | C20: LTA North | D20: Medium | E20: 9-12 | F20: =IF($E20="","",IFERROR(LOOKUP(VALUE(LEFT($E20&"",FIND("-",$E20&"-")-1)),$C$34:$C$39,$D$34:$D$39),"")) -> 0 | G20: 0 | H20: =IF($G20="","n/a",IF($F20=$G20,"ok","MISMATCH")) -> ok | I20: 55000 | L20: Sentinels
B21: GAM Esports | C21: LCP | D21: Low | E21: 9-12 | F21: =IF($E21="","",IFERROR(LOOKUP(VALUE(LEFT($E21&"",FIND("-",$E21&"-")-1)),$C$34:$C$39,$D$34:$D$39),"")) -> 0 | G21: 0 | H21: =IF($G21="","n/a",IF($F21=$G21,"ok","MISMATCH")) -> ok | I21: 55000 | L21: GAM Esports
B22: MIBR.LOS | C22: LTA South | D22: Low | E22: 9-12 | F22: =IF($E22="","",IFERROR(LOOKUP(VALUE(LEFT($E22&"",FIND("-",$E22&"-")-1)),$C$34:$C$39,$D$34:$D$39),"")) -> 0 | G22: 0 | H22: =IF($G22="","n/a",IF($F22=$G22,"ok","MISMATCH")) -> ok | I22: 55000 | L22: MIBR.LOS
B23: FURIA | C23: LTA South | D23: Low | E23: 13-16 | F23: =IF($E23="","",IFERROR(LOOKUP(VALUE(LEFT($E23&"",FIND("-",$E23&"-")-1)),$C$34:$C$39,$D$34:$D$39),"")) -> 0 | G23: 0 | H23: =IF($G23="","n/a",IF($F23=$G23,"ok","MISMATCH")) -> ok | I23: 30000 | L23: FURIA
... B26: LYON | C26: LTA North | D26: Low | E26: 13-16 | F26: =IF($E26="","",IFERROR(LOOKUP(VALUE(LEFT($E26&"",FIND("-",$E26&"-")-1)),$C$34:$C$39,$D$34:$D$39),"")) -> 0 | G26: 0 | H26: =IF($G26="","n/a",IF($F26=$G26,"ok","MISMATCH")) -> ok | I26: 30000 | L26: LYON
B28: TOTAL POINTS AWARDED | F28: =SUM(F11:F26) -> 3350
B29: 3,350 club points awarded. Prize money sums to $2,000,000 of the $2,025,000 pool — the $25,000 balance is an MVP award, as in CS2.
B31: 2 · POINT SYSTEM
B32: From the Liquipedia prize table. Identical curve to CS2 and Chess: club points stop after 8th, prize money continues to 16th.
B33: From place | C33: Club points | D33: Band
C34: 1 | D34: 1000 | E34: 1st
C35: 2 | D35: 750 | E35: 2nd
C36: 3 | D36: 500 | E36: 3rd
C37: 4 | D37: 300 | E37: 4th
C38: 5 | D38: 200 | E38: 5th-8th
C39: 9 | D39: 0 | E39: 9th-16th (prize money only)
B41: 3 · COHORT MODEL — how a band becomes a number the simulator can use
B42: A cohort is not a seed, it is a RANGE. The simulator never collapses a band to a single rank — that would create artificial ties and understate variance. Instead each cohort maps to a latent strength distribution: a mean position (the midpoint of its band) and a spread (how uncertain we are within the band). On every run each team draws a strength value from its own distribution, the field is re-ranked by those draws, and the resulting order becomes that run's finishing order. Two independent noise sources are combined: SEED UNCERTAINTY (we do not know the order inside a cohort) and TITLE VOLATILITY (the title scrambles outcomes regardless of seed). They add in quadrature — sigma_total = SQRT(sigma_within^2 + sigma_title^2) — because they are independent. This is why the same machinery serves every seed method: a VRS rating gives a precise mean and a small sigma_within; a cohort gives a coarse mean and a large one. Change a team's cohort and its mean moves; change the TVI and every team's spread moves together.
B48: Cohort | C48: Teams (auto) | D48: Band from (auto) | E48: Band to (auto) | F48: Mean position (mu) | G48: Within-cohort sigma | H48: Title sigma | I48: Total sigma
B49: High | C49: =COUNTIF($D$11:$D$26,$B49) -> 7 | D49: =1 -> 1 | E49: =D49+C49-1 -> 7 | F49: =(D49+E49)/2 -> 4 | G49: =(E49-D49+1)/SQRT(12) -> 2.0207259 | H49: =$D$54/100*$D$55/2 -> 3.2 | I49: =SQRT(G49^2+H49^2) -> 3.784618
B50: Medium | C50: =COUNTIF($D$11:$D$26,$B50) -> 4 | D50: =E49+1 -> 8 | E50: =D50+C50-1 -> 11 | F50: =(D50+E50)/2 -> 9.5 | G50: =(E50-D50+1)/SQRT(12) -> 1.1547005 | H50: =$D$54/100*$D$55/2 -> 3.2 | I50: =SQRT(G50^2+H50^2) -> 3.4019602
B51: Low | C51: =COUNTIF($D$11:$D$26,$B51) -> 5 | D51: =E50+1 -> 12 | E51: =D51+C51-1 -> 16 | F51: =(D51+E51)/2 -> 14 | G51: =(E51-D51+1)/SQRT(12) -> 1.4433757 | H51: =$D$54/100*$D$55/2 -> 3.2 | I51: =SQRT(G51^2+H51^2) -> 3.5104606
B53: Bands derive automatically from the cohort dropdowns above — reassign a team and every band, mu and sigma updates. Only the two blue cells below are inputs.
B54: TVI (title volatility) | D54: 40
...

Sheet PUBG Mobile
B2: PUBG Mobile — EWC 2026
B3: Battle royale. Listed on Liquipedia as 'PUBG Mobile World Cup 2026'. Every placement 1-8 pays a DIFFERENT club-point value — no shared bands, unlike the playoff titles.
B5: FORMAT | D5: FIELD SIZE | F5: TVI | H5: SEED METHOD | J5: SEED SOURCE | L5: PLACEMENT GRANULARITY
B6: Groups → Survival Stage → Grand Finals | D6: 32 teams | F6: 78 · High | H6: E — no credible seed | J6: n/a — see block 3 | L6: Exact 1-26, ties from 27th
B8: 1 · FIELD & RESULTS
B9: All 32 teams with exact placements and prize money from the Liquipedia prize table. Seed column is deliberately empty — see the seed note in block 3. Qualification route and region are recorded as data, not used as a seed.
B10: Club | C10: Region | D10: Seed | E10: Placement | F10: Points (auto) | G10: Official CC pts | H10: Δ check | I10: Prize (USD) | J10: Qualification route | L10: Club (canonical)
B11: S2G Esports | C11: Türkiye | E11: 1 | F11: =IF($E11="","",IFERROR(LOOKUP(VALUE(LEFT($E11&"",FIND("-",$E11&"-")-1)),$C$47:$C$55,$D$47:$D$55),"")) -> 1000 | G11: 1000 | H11: =IF($G11="","n/a",IF($F11=$G11,"ok","MISMATCH")) -> ok | I11: 555000 | J11: Türkiye Points (top 4) | L11: S2G Esports
B12: Nongshim RedForce | C12: Korea | E12: 2 | F12: =IF($E12="","",IFERROR(LOOKUP(VALUE(LEFT($E12&"",FIND("-",$E12&"-")-1)),$C$47:$C$55,$D$47:$D$55),"")) -> 750 | G12: 750 | H12: =IF($G12="","n/a",IF($F12=$G12,"ok","MISMATCH")) -> ok | I12: 293000 | J12: Korea (champion) | L12: Nongshim RedForce
B13: Aurora Gaming | C13: EECA | E13: 3 | F13: =IF($E13="","",IFERROR(LOOKUP(VALUE(LEFT($E13&"",FIND("-",$E13&"-")-1)),$C$47:$C$55,$D$47:$D$55),"")) -> 500 | G13: 500 | H13: =IF($G13="","n/a",IF($F13=$G13,"ok","MISMATCH")) -> ok | I13: 210000 | J13: EECA Points (top 3) | L13: Aurora Gaming
B14: eArena | C14: SEA | E14: 4 | F14: =IF($E14="","",IFERROR(LOOKUP(VALUE(LEFT($E14&"",FIND("-",$E14&"-")-1)),$C$47:$C$55,$D$47:$D$55),"")) -> 300 | G14: 300 | H14: =IF($G14="","n/a",IF($F14=$G14,"ok","MISMATCH")) -> ok | I14: 161000 | J14: Southeast Asia Points (top 4) | L14: eArena
B15: Tianba | C15: China | E15: 5 | F15: =IF($E15="","",IFERROR(LOOKUP(VALUE(LEFT($E15&"",FIND("-",$E15&"-")-1)),$C$47:$C$55,$D$47:$D$55),"")) -> 200 | G15: 200 | H15: =IF($G15="","n/a",IF($F15=$G15,"ok","MISMATCH")) -> ok | I15: 141000 | J15: 2026 PEL Points (top 3) | L15: Tianba
B16: 4Thrives Esports | C16: South Asia | E16: 6 | F16: =IF($E16="","",IFERROR(LOOKUP(VALUE(LEFT($E16&"",FIND("-",$E16&"-")-1)),$C$47:$C$55,$D$47:$D$55),"")) -> 150 | H16: =IF($G16="","n/a",IF($F16=$G16,"ok","MISMATCH")) -> n/a | I16: 161000 | J16: South Asia Points (top 2) | L16: 4thrives Esports
B17: Team Flash | C17: SEA | E17: 7 | F17: =IF($E17="","",IFERROR(LOOKUP(VALUE(LEFT($E17&"",FIND("-",$E17&"-")-1)),$C$47:$C$55,$D$47:$D$55),"")) -> 100 | G17: 100 | H17: =IF($G17="","n/a",IF($F17=$G17,"ok","MISMATCH")) -> ok | I17: 137500 | J17: Southeast Asia Points (top 4) | L17: Team Flash
B18: Horaa Esports | C18: South Asia | E18: 8 | F18: =IF($E18="","",IFERROR(LOOKUP(VALUE(LEFT($E18&"",FIND("-",$E18&"-")-1)),$C$47:$C$55,$D$47:$D$55),"")) -> 50 | G18: 50 | H18: =IF($G18="","n/a",IF($F18=$G18,"ok","MISMATCH")) -> ok | I18: 127500 | J18: South Asia Points (top 2) | L18: Horaa Esports
B19: Nigma Galaxy | C19: MENA | E19: 9 | F19: =IF($E19="","",IFERROR(LOOKUP(VALUE(LEFT($E19&"",FIND("-",$E19&"-")-1)),$C$47:$C$55,$D$47:$D$55),"")) -> 0 | G19: 0 | H19: =IF($G19="","n/a",IF($F19=$G19,"ok","MISMATCH")) -> ok | I19: 115000 | J19: MENA Points (top 5) | L19: Nigma Galaxy
B20: FURIA | C20: Americas | E20: 10 | F20: =IF($E20="","",IFERROR(LOOKUP(VALUE(LEFT($E20&"",FIND("-",$E20&"-")-1)),$C$47:$C$55,$D$47:$D$55),"")) -> 0 | G20: 0 | H20: =IF($G20="","n/a",IF($F20=$G20,"ok","MISMATCH")) -> ok | I20: 95000 | J20: Americas Points (top 3) | L20: FURIA
B21: ULF Esports | C21: Türkiye | E21: 11 | F21: =IF($E21="","",IFERROR(LOOKUP(VALUE(LEFT($E21&"",FIND("-",$E21&"-")-1)),$C$47:$C$55,$D$47:$D$55),"")) -> 0 | H21: =IF($G21="","n/a",IF($F21=$G21,"ok","MISMATCH")) -> n/a | I21: 92000 | J21: Türkiye Points (top 4) | L21: ULF Esports
B22: Team Vitality | C22: SEA | E22: 12 | F22: =IF($E22="","",IFERROR(LOOKUP(VALUE(LEFT($E22&"",FIND("-",$E22&"-")-1)),$C$47:$C$55,$D$47:$D$55),"")) -> 0 | G22: 0 | H22: =IF($G22="","n/a",IF($F22=$G22,"ok","MISMATCH")) -> ok | I22: 116000 | J22: Southeast Asia Points (as Bigetron by Vitality) | L22: Team Vitality
B23: GodLike Esports | C23: India | E23: 13 | F23: =IF($E23="","",IFERROR(LOOKUP(VALUE(LEFT($E23&"",FIND("-",$E23&"-")-1)),$C$47:$C$55,$D$47:$D$55),"")) -> 0 | H23: =IF($G23="","n/a",IF($F23=$G23,"ok","MISMATCH")) -> n/a | I23: 100000 | J23: 2026 BGMI Pro Series (champion) | L23: GodLike
B24: AlUla Club Esports | C24: MENA | E24: 14 | F24: =IF($E24="","",IFERROR(LOOKUP(VALUE(LEFT($E24&"",FIND("-",$E24&"-")-1)),$C$47:$C$55,$D$47:$D$55),"")) -> 0 | H24: =IF($G24="","n/a",IF($F24=$G24,"ok","MISMATCH")) -> n/a | I24: 76000 | J24: MENA Points (top 5) | L24: AlUla Club Esports
B25: Orangutan | C25: India | E25: 15 | F25: =IF($E25="","",IFERROR(LOOKUP(VALUE(LEFT($E25&"",FIND("-",$E25&"-")-1)),$C$47:$C$55,$D$47:$D$55),"")) -> 0 | H25: =IF($G25="","n/a",IF($F25=$G25,"ok","MISMATCH")) -> n/a | I25: 95000 | J25: 2026 India Points (champion) | L25: Orangutan
B26: IDA Esports | C26: Türkiye | E26: 16 | F26: =IF($E26="","",IFERROR(LOOKUP(VALUE(LEFT($E26&"",FIND("-",$E26&"-")-1)),$C$47:$C$55,$D$47:$D$55),"")) -> 0 | H26: =IF($G26="","n/a",IF($F26=$G26,"ok","MISMATCH")) -> n/a | I26: 90000 | J26: Türkiye Points (top 4) | L26: IDA Esports
B27: Wolves Esports | C27: Americas | E27: 17 | F27: =IF($E27="","",IFERROR(LOOKUP(VALUE(LEFT($E27&"",FIND("-",$E27&"-")-1)),$C$47:$C$55,$D$47:$D$55),"")) -> 0 | G27: 0 | H27: =IF($G27="","n/a",IF($F27=$G27,"ok","MISMATCH")) -> ok | I27: 34000 | J27: Americas Points (top 3) | L27: Wolves Esports
B28: GOAT Team | C28: EECA | E28: 18 | F28: =IF($E28="","",IFERROR(LOOKUP(VALUE(LEFT($E28&"",FIND("-",$E28&"-")-1)),$C$47:$C$55,$D$47:$D$55),"")) -> 0 | H28: =IF($G28="","n/a",IF($F28=$G28,"ok","MISMATCH")) -> n/a | I28: 37000 | J28: EECA Points (top 3) | L28: GOAT Team
B29: Alpha7 Esports | C29: Americas | E29: 19 | F29: =IF($E29="","",IFERROR(LOOKUP(VALUE(LEFT($E29&"",FIND("-",$E29&"-")-1)),$C$47:$C$55,$D$47:$D$55),"")) -> 0 | H29: =IF($G29="","n/a",IF($F29=$G29,"ok","MISMATCH")) -> n/a | I29: 36000 | J29: Americas Points (top 3) | L29: Alpha7 Esports
B30: AG.AL International | C30: China | E30: 20 | F30: =IF($E30="","",IFERROR(LOOKUP(VALUE(LEFT($E30&"",FIND("-",$E30&"-")-1)),$C$47:$C$55,$D$47:$D$55),"")) -> 0 | G30: 0 | H30: =IF($G30="","n/a",IF($F30=$G30,"ok","MISMATCH")) -> ok | I30: 36000 | J30: 2026 PEL Points (as All Gamers) | L30: AG.AL International
B31: DOPENESS | C31: Japan | E31: 21 | F31: =IF($E31="","",IFERROR(LOOKUP(VALUE(LEFT($E31&"",FIND("-",$E31&"-")-1)),$C$47:$C$55,$D$47:$D$55),"")) -> 0 | H31: =IF($G31="","n/a",IF($F31=$G31,"ok","MISMATCH")) -> n/a | I31: 29000 | J31: Japan (champion) | L31: DOPENESS
B32: Geekay Esports | C32: MENA | E32: 22 | F32: =IF($E32="","",IFERROR(LOOKUP(VALUE(LEFT($E32&"",FIND("-",$E32&"-")-1)),$C$47:$C$55,$D$47:$D$55),"")) -> 0 | G32: 0 | H32: =IF($G32="","n/a",IF($F32=$G32,"ok","MISMATCH")) -> ok | I32: 28000 | J32: MENA Points (top 5) | L32: Geekay Esports
B33: Rex Regum Qeon | C33: SEA | E33: 23 | F33: =IF($E33="","",IFERROR(LOOKUP(VALUE(LEFT($E33&"",FIND("-",$E33&"-")-1)),$C$47:$C$55,$D$47:$D$55),"")) -> 0 | G33: 0 | H33: =IF($G33="","n/a",IF($F33=$G33,"ok","MISMATCH")) -> ok | I33: 28000 | J33: Southeast Asia Points (as RRQ RYU) | L33: Rex Regum Qeon
B34: Yangon Galacticos | C34: SEA | E34: 24 | F34: =IF($E34="","",IFERROR(LOOKUP(VALUE(LEFT($E34&"",FIND("-",$E34&"-")-1)),$C$47:$C$55,$D$47:$D$55),"")) -> 0 | G34: 0 | H34: =IF($G34="","n/a",IF($F34=$G34,"ok","MISMATCH")) -> ok | I34: 30000 | J34: 2025 PMWC (defending champion) | L34: Yangon Galacticos
B35: DRX | C35: Korea | E35: 25 | F35: =IF($E35="","",IFERROR(LOOKUP(VALUE(LEFT($E35&"",FIND("-",$E35&"-")-1)),$C$47:$C$55,$D$47:$D$55),"")) -> 0 | G35: 0 | H35: =IF($G35="","n/a",IF($F35=$G35,"ok","MISMATCH")) -> ok | I35: 27000 | J35: 2026 Rivals Cup (champion) | L35: DRX
B36: GS 721 | C36: MENA | E36: 26 | F36: =IF($E36="","",IFERROR(LOOKUP(VALUE(LEFT($E36&"",FIND("-",$E36&"-")-1)),$C$47:$C$55,$D$47:$D$55),"")) -> 0 | H36: =IF($G36="","n/a",IF($F36=$G36,"ok","MISMATCH")) -> n/a | I36: 27000 | J36: MENA Points (as 721 Esports) | L36: GS 721
B37: XForce Rejects | C37: Africa | E37: 27-28 | F37: =IF($E37="","",IFERROR(LOOKUP(VALUE(LEFT($E37&"",FIND("-",$E37&"-")-1)),$C$47:$C$55,$D$47:$D$55),"")) -> 0 | H37: =IF($G37="","n/a",IF($F37=$G37,"ok","MISMATCH")) -> n/a | I37: 21000 | J37: Africa Points (champion) | L37: XForce Rejects
B38: ETSH Esports | C38: MENA | E38: 27-28 | F38: =IF($E38="","",IFERROR(LOOKUP(VALUE(LEFT($E38&"",FIND("-",$E38&"-")-1)),$C$47:$C$55,$D$47:$D$55),"")) -> 0 | H38: =IF($G38="","n/a",IF($F38=$G38,"ok","MISMATCH")) -> n/a | I38: 21000 | J38: MENA Points (top 5) | L38: ETSH Esports
B39: ThunderTalk Gaming | C39: China | E39: 29-30 | F39: =IF($E39="","",IFERROR(LOOKUP(VALUE(LEFT($E39&"",FIND("-",$E39&"-")-1)),$C$47:$C$55,$D$47:$D$55),"")) -> 0 | H39: =IF($G39="","n/a",IF($F39=$G39,"ok","MISMATCH")) -> n/a | I39: 20500 | J39: 2026 PEL Points (top 3) | L39: ThunderTalk Gaming
B40: TT Project | C40: EECA | E40: 29-30 | F40: =IF($E40="","",IFERROR(LOOKUP(VALUE(LEFT($E40&"",FIND("-",$E40&"-")-1)),$C$47:$C$55,$D$47:$D$55),"")) -> 0 | H40: =IF($G40="","n/a",IF($F40=$G40,"ok","MISMATCH")) -> n/a | I40: 20500 | J40: EECA Points (top 3) | L40: TT Project
B41: Gaming Stars Esports | C41: Türkiye | E41: 31-32 | F41: =IF($E41="","",IFERROR(LOOKUP(VALUE(LEFT($E41&"",FIND("-",$E41&"-")-1)),$C$47:$C$55,$D$47:$D$55),"")) -> 0 | H41: =IF($G41="","n/a",IF($F41=$G41,"ok","MISMATCH")) -> n/a | I41: 20000 | J41: Türkiye Points (top 4) | L41: Gaming Stars Esports
B42: Hustler Crew | C42: W. Europe | E42: 31-32 | F42: =IF($E42="","",IFERROR(LOOKUP(VALUE(LEFT($E42&"",FIND("-",$E42&"-")-1)),$C$47:$C$55,$D$47:$D$55),"")) -> 0 | H42: =IF($G42="","n/a",IF($F42=$G42,"ok","MISMATCH")) -> n/a | I42: 20000 | J42: Western Europe Points (champion) | L42: Hustler Crew
B44: TOTAL POINTS AWARDED | F44: =SUM(F11:F42) -> 3050
...

Sheet Fortnite Reload
B2: Fortnite Reload — EWC 2026
B3: Duos battle royale. Listed on Liquipedia as 'Reload Elite Series 2026 - Championship'. Same BR point curve as PUBG Mobile: every placement 1-8 pays a different value.
B5: FORMAT | D5: FIELD SIZE | F5: TVI | H5: SEED METHOD | J5: SEED SOURCE | L5: PLACEMENT GRANULARITY
B6: Duos BR — Reload mode | D6: 40 duos | F6: 80 · High | H6: E + elite override (hybrid) | J6: Reload-format results only — see block 3 | L6: Exact 1-34, ties from 35th
B8: 1 · FIELD & RESULTS
B9: All 40 duos with exact placements and prize money. Tier column is the hybrid seed input — default is Field for everyone, which behaves exactly as method E until you promote a duo to Elite.
B10: Club | C10: Duo | D10: Tier | E10: Placement | F10: Points (auto) | G10: Official CC pts | H10: Δ check | I10: Prize (USD) | J10: Notes | L10: Club (canonical)
B11: BIG | C11: vic0 & Malibuca | D11: Field | E11: 1 | F11: =IF($E11="","",IFERROR(LOOKUP(VALUE(LEFT($E11&"",FIND("-",$E11&"-")-1)),$C$57:$C$65,$D$57:$D$65),"")) -> 1000 | G11: 1000 | H11: =IF($G11="","n/a",IF($F11=$G11,"ok","MISMATCH")) -> ok | I11: 260000 | L11: BIG
B12: Mixed | C12: Momsy & SkyJump | D12: Field | E12: 2 | F12: =IF($E12="","",IFERROR(LOOKUP(VALUE(LEFT($E12&"",FIND("-",$E12&"-")-1)),$C$57:$C$65,$D$57:$D$65),"")) -> 750 | H12: =IF($G12="","n/a",IF($F12=$G12,"ok","MISMATCH")) -> n/a | I12: 150000 | J12: Momsy: Lyost Esport / SkyJump: Ravens Esports | L12: Mixed
B13: Aurora Gaming | C13: shxrk & t3eny | D13: Field | E13: 3 | F13: =IF($E13="","",IFERROR(LOOKUP(VALUE(LEFT($E13&"",FIND("-",$E13&"-")-1)),$C$57:$C$65,$D$57:$D$65),"")) -> 500 | G13: 500 | H13: =IF($G13="","n/a",IF($F13=$G13,"ok","MISMATCH")) -> ok | I13: 90000 | L13: Aurora Gaming
B14: HavoK by Vitality | C14: SwizzY & Pixie | D14: Field | E14: 4 | F14: =IF($E14="","",IFERROR(LOOKUP(VALUE(LEFT($E14&"",FIND("-",$E14&"-")-1)),$C$57:$C$65,$D$57:$D$65),"")) -> 300 | H14: =IF($G14="","n/a",IF($F14=$G14,"ok","MISMATCH")) -> n/a | I14: 60000 | J14: Scored as a separate club — canonical join changed to HavoK by Vitality | L14: HavoK by Vitality
B15: Leviatán | C15: Lewa & Romero | D15: Field | E15: 5 | F15: =IF($E15="","",IFERROR(LOOKUP(VALUE(LEFT($E15&"",FIND("-",$E15&"-")-1)),$C$57:$C$65,$D$57:$D$65),"")) -> 200 | G15: 200 | H15: =IF($G15="","n/a",IF($F15=$G15,"ok","MISMATCH")) -> ok | I15: 45000 | L15: Leviatán
B16: ROC Esports | C16: charyy & Kami | D16: Field | E16: 6 | F16: =IF($E16="","",IFERROR(LOOKUP(VALUE(LEFT($E16&"",FIND("-",$E16&"-")-1)),$C$57:$C$65,$D$57:$D$65),"")) -> 150 | G16: 150 | H16: =IF($G16="","n/a",IF($F16=$G16,"ok","MISMATCH")) -> ok | I16: 35000 | L16: ROC Esports
B17: Dignitas | C17: VicterV & Khanada | D17: Field | E17: 7 | F17: =IF($E17="","",IFERROR(LOOKUP(VALUE(LEFT($E17&"",FIND("-",$E17&"-")-1)),$C$57:$C$65,$D$57:$D$65),"")) -> 100 | G17: 100 | H17: =IF($G17="","n/a",IF($F17=$G17,"ok","MISMATCH")) -> ok | I17: 30000 | L17: Dignitas
B18: T1 | C18: Demus & Darm | D18: Field | E18: 8 | F18: =IF($E18="","",IFERROR(LOOKUP(VALUE(LEFT($E18&"",FIND("-",$E18&"-")-1)),$C$57:$C$65,$D$57:$D$65),"")) -> 50 | G18: 50 | H18: =IF($G18="","n/a",IF($F18=$G18,"ok","MISMATCH")) -> ok | I18: 28000 | L18: T1
B19: S8UL Esports | C19: Faded & Kaan | D19: Field | E19: 9 | F19: =IF($E19="","",IFERROR(LOOKUP(VALUE(LEFT($E19&"",FIND("-",$E19&"-")-1)),$C$57:$C$65,$D$57:$D$65),"")) -> 0 | G19: 0 | H19: =IF($G19="","n/a",IF($F19=$G19,"ok","MISMATCH")) -> ok | I19: 26000 | L19: S8UL Esports
B20: Vision Esports | C20: SaLva & Yassen | D20: Field | E20: 10 | F20: =IF($E20="","",IFERROR(LOOKUP(VALUE(LEFT($E20&"",FIND("-",$E20&"-")-1)),$C$57:$C$65,$D$57:$D$65),"")) -> 0 | H20: =IF($G20="","n/a",IF($F20=$G20,"ok","MISMATCH")) -> n/a | I20: 24000 | L20: Team Vision
B21: AG.AL International | C21: Sky & Scroll | D21: Field | E21: 11 | F21: =IF($E21="","",IFERROR(LOOKUP(VALUE(LEFT($E21&"",FIND("-",$E21&"-")-1)),$C$57:$C$65,$D$57:$D$65),"")) -> 0 | G21: 0 | H21: =IF($G21="","n/a",IF($F21=$G21,"ok","MISMATCH")) -> ok | I21: 22000 | L21: AG.AL International
B22: Team Falcons | C22: Peterbot & Pollo | D22: Field | E22: 12 | F22: =IF($E22="","",IFERROR(LOOKUP(VALUE(LEFT($E22&"",FIND("-",$E22&"-")-1)),$C$57:$C$65,$D$57:$D$65),"")) -> 0 | G22: 0 | H22: =IF($G22="","n/a",IF($F22=$G22,"ok","MISMATCH")) -> ok | I22: 20000 | L22: Team Falcons
B23: Team Vitality | C23: Tjino & PabloWingu | D23: Field | E23: 13 | F23: =IF($E23="","",IFERROR(LOOKUP(VALUE(LEFT($E23&"",FIND("-",$E23&"-")-1)),$C$57:$C$65,$D$57:$D$65),"")) -> 0 | G23: 0 | H23: =IF($G23="","n/a",IF($F23=$G23,"ok","MISMATCH")) -> ok | I23: 18000 | L23: Team Vitality
B24: Elite Esports | C24: josh & Eomzo | D24: Field | E24: 14 | F24: =IF($E24="","",IFERROR(LOOKUP(VALUE(LEFT($E24&"",FIND("-",$E24&"-")-1)),$C$57:$C$65,$D$57:$D$65),"")) -> 0 | G24: 0 | H24: =IF($G24="","n/a",IF($F24=$G24,"ok","MISMATCH")) -> ok | I24: 16000 | L24: Elite Esports
B25: Mixed | C25: Minipiyo & FuuKun | D25: Field | E25: 15 | F25: =IF($E25="","",IFERROR(LOOKUP(VALUE(LEFT($E25&"",FIND("-",$E25&"-")-1)),$C$57:$C$65,$D$57:$D$65),"")) -> 0 | H25: =IF($G25="","n/a",IF($F25=$G25,"ok","MISMATCH")) -> n/a | I25: 15000 | J25: Minipiyo: ZETA DIVISION / FuuKun: QT DIG | L25: Mixed
B26: Team Orchid | C26: Nociff & Izzi | D26: Field | E26: 16 | F26: =IF($E26="","",IFERROR(LOOKUP(VALUE(LEFT($E26&"",FIND("-",$E26&"-")-1)),$C$57:$C$65,$D$57:$D$65),"")) -> 0 | H26: =IF($G26="","n/a",IF($F26=$G26,"ok","MISMATCH")) -> n/a | I26: 14000 | L26: Team Orchid
B27: Mixed | C27: Muz & Sphinx | D27: Field | E27: 17 | F27: =IF($E27="","",IFERROR(LOOKUP(VALUE(LEFT($E27&"",FIND("-",$E27&"-")-1)),$C$57:$C$65,$D$57:$D$65),"")) -> 0 | H27: =IF($G27="","n/a",IF($F27=$G27,"ok","MISMATCH")) -> n/a | I27: 13000 | J27: Muz: XSET / Sphinx: unlisted | L27: Mixed
B28: Twisted Minds | C28: Cold & Rapid | D28: Field | E28: 18 | F28: =IF($E28="","",IFERROR(LOOKUP(VALUE(LEFT($E28&"",FIND("-",$E28&"-")-1)),$C$57:$C$65,$D$57:$D$65),"")) -> 0 | G28: 0 | H28: =IF($G28="","n/a",IF($F28=$G28,"ok","MISMATCH")) -> ok | I28: 12000 | L28: Twisted Minds
B29: Mixed | C29: Goofy & ZDog | D29: Field | E29: 19 | F29: =IF($E29="","",IFERROR(LOOKUP(VALUE(LEFT($E29&"",FIND("-",$E29&"-")-1)),$C$57:$C$65,$D$57:$D$65),"")) -> 0 | H29: =IF($G29="","n/a",IF($F29=$G29,"ok","MISMATCH")) -> n/a | I29: 11000 | J29: Goofy: PWR / ZDog: JFT Esports | L29: Mixed
B30: Twisted Minds | C30: Acorn & Boltz | D30: Field | E30: 20 | F30: =IF($E30="","",IFERROR(LOOKUP(VALUE(LEFT($E30&"",FIND("-",$E30&"-")-1)),$C$57:$C$65,$D$57:$D$65),"")) -> 0 | H30: =IF($G30="","n/a",IF($F30=$G30,"ok","MISMATCH")) -> n/a | I30: 10000 | L30: Twisted Minds
B31: ZETA DIVISION | C31: Koyota & yuma | D31: Field | E31: 21 | F31: =IF($E31="","",IFERROR(LOOKUP(VALUE(LEFT($E31&"",FIND("-",$E31&"-")-1)),$C$57:$C$65,$D$57:$D$65),"")) -> 0 | G31: 0 | H31: =IF($G31="","n/a",IF($F31=$G31,"ok","MISMATCH")) -> ok | I31: 9500 | L31: ZETA DIVISION
B32: Mixed | C32: Bugha & Braydz | D32: Field | E32: 22 | F32: =IF($E32="","",IFERROR(LOOKUP(VALUE(LEFT($E32&"",FIND("-",$E32&"-")-1)),$C$57:$C$65,$D$57:$D$65),"")) -> 0 | H32: =IF($G32="","n/a",IF($F32=$G32,"ok","MISMATCH")) -> n/a | I32: 9000 | J32: Braydz: XP42 Esports / Bugha: unlisted | L32: Mixed
B33: FURIA | C33: Night & 916Gon | D33: Field | E33: 23 | F33: =IF($E33="","",IFERROR(LOOKUP(VALUE(LEFT($E33&"",FIND("-",$E33&"-")-1)),$C$57:$C$65,$D$57:$D$65),"")) -> 0 | G33: 0 | H33: =IF($G33="","n/a",IF($F33=$G33,"ok","MISMATCH")) -> ok | I33: 8500 | L33: FURIA
B34: Mixed | C34: Cringe & Volko | D34: Field | E34: 24 | F34: =IF($E34="","",IFERROR(LOOKUP(VALUE(LEFT($E34&"",FIND("-",$E34&"-")-1)),$C$57:$C$65,$D$57:$D$65),"")) -> 0 | H34: =IF($G34="","n/a",IF($F34=$G34,"ok","MISMATCH")) -> n/a | I34: 8000 | J34: Cringe: 7VEN / Volko: Northern Star Gaming | L34: Mixed
B35: JOGO | C35: Oatley & Spookz | D35: Field | E35: 25 | F35: =IF($E35="","",IFERROR(LOOKUP(VALUE(LEFT($E35&"",FIND("-",$E35&"-")-1)),$C$57:$C$65,$D$57:$D$65),"")) -> 0 | H35: =IF($G35="","n/a",IF($F35=$G35,"ok","MISMATCH")) -> n/a | I35: 7500 | L35: JOGO
B36: REJECT | C36: Mofu & tomat | D36: Field | E36: 26 | F36: =IF($E36="","",IFERROR(LOOKUP(VALUE(LEFT($E36&"",FIND("-",$E36&"-")-1)),$C$57:$C$65,$D$57:$D$65),"")) -> 0 | G36: 0 | H36: =IF($G36="","n/a",IF($F36=$G36,"ok","MISMATCH")) -> ok | I36: 7000 | L36: REJECT
B37: Mixed | C37: Mshary & 5aald | D37: Field | E37: 27 | F37: =IF($E37="","",IFERROR(LOOKUP(VALUE(LEFT($E37&"",FIND("-",$E37&"-")-1)),$C$57:$C$65,$D$57:$D$65),"")) -> 0 | H37: =IF($G37="","n/a",IF($F37=$G37,"ok","MISMATCH")) -> n/a | I37: 6500 | J37: Mshary: Vision Esports / 5aald: unlisted | L37: Mixed
B38: RVL ESPORT | C38: Moda & Rew | D38: Field | E38: 28 | F38: =IF($E38="","",IFERROR(LOOKUP(VALUE(LEFT($E38&"",FIND("-",$E38&"-")-1)),$C$57:$C$65,$D$57:$D$65),"")) -> 0 | H38: =IF($G38="","n/a",IF($F38=$G38,"ok","MISMATCH")) -> n/a | I38: 6000 | L38: RVL ESPORT
B39: Mixed | C39: Vazen & Anon | D39: Field | E39: 29 | F39: =IF($E39="","",IFERROR(LOOKUP(VALUE(LEFT($E39&"",FIND("-",$E39&"-")-1)),$C$57:$C$65,$D$57:$D$65),"")) -> 0 | H39: =IF($G39="","n/a",IF($F39=$G39,"ok","MISMATCH")) -> n/a | I39: 5500 | J39: Vazen: Coast Esports / Anon: PWR | L39: Mixed
B40: Geekay Esports | C40: panzer & Japko | D40: Field | E40: 30 | F40: =IF($E40="","",IFERROR(LOOKUP(VALUE(LEFT($E40&"",FIND("-",$E40&"-")-1)),$C$57:$C$65,$D$57:$D$65),"")) -> 0 | G40: 0 | H40: =IF($G40="","n/a",IF($F40=$G40,"ok","MISMATCH")) -> ok | I40: 5000 | L40: Geekay Esports
B41: FUT Esports | C41: Edson & Phzin | D41: Field | E41: 31 | F41: =IF($E41="","",IFERROR(LOOKUP(VALUE(LEFT($E41&"",FIND("-",$E41&"-")-1)),$C$57:$C$65,$D$57:$D$65),"")) -> 0 | G41: 0 | H41: =IF($G41="","n/a",IF($F41=$G41,"ok","MISMATCH")) -> ok | I41: 4500 | L41: FUT Esports
B42: Mixed | C42: Shadow & Vergo | D42: Field | E42: 32 | F42: =IF($E42="","",IFERROR(LOOKUP(VALUE(LEFT($E42&"",FIND("-",$E42&"-")-1)),$C$57:$C$65,$D$57:$D$65),"")) -> 0 | H42: =IF($G42="","n/a",IF($F42=$G42,"ok","MISMATCH")) -> n/a | I42: 4000 | J42: Shadow: Natrix Esports / Vergo: Gentle Mates | L42: Mixed
B43: Unlisted | C43: Aoxy & Jojofishy | D43: Field | E43: 33 | F43: =IF($E43="","",IFERROR(LOOKUP(VALUE(LEFT($E43&"",FIND("-",$E43&"-")-1)),$C$57:$C$65,$D$57:$D$65),"")) -> 0 | H43: =IF($G43="","n/a",IF($F43=$G43,"ok","MISMATCH")) -> n/a | I43: 3500 | L43: Unlisted
...

Sheet Trackmania
B2: Trackmania — EWC 2026
B3: 1v1 racing. Seeds from the Elite Cup 2026 final standings — Ubisoft Nadeo's official Road-to-EWC ladder, method A.
B5: FORMAT | D5: FIELD SIZE | F5: TVI | H5: SEED METHOD | J5: SEED SOURCE | L5: PLACEMENT GRANULARITY
B6: Knockout, 32 players | D6: 32 players | F6: 22 · Low | H6: A — official qualification ladder | J6: Elite Cup 2026 standings (Feb–May 26) | L6: Bands (5-6, 7-8, then fours)
B8: 1 · FIELD & RESULTS
B9: All 32 players. Seed is the field ranked 1-32 by Elite Cup finishing position; the raw Elite Cup rank is kept alongside so the gap between ladder form and event result stays visible.
B10: Club | C10: Player | D10: Seed | E10: Elite Cup rank | F10: Placement | G10: Points (auto) | H10: Official CC pts | I10: Δ check | J10: Prize (USD) | K10: Notes | M10: Club (canonical)
B11: AG.AL International | C11: Gwen | D11: 9 | E11: 9 | F11: 1 | G11: =IF($F11="","",IFERROR(LOOKUP(VALUE(LEFT($F11&"",FIND("-",$F11&"-")-1)),$C$50:$C$56,$D$50:$D$56),"")) -> 1000 | H11: 1000 | I11: =IF($H11="","n/a",IF($G11=$H11,"ok","MISMATCH")) -> ok | J11: 130000 | K11: competes as All Gamers Global | M11: AG.AL International
B12: Team Liquid | C12: Epos | D12: 17 | E12: 18 | F12: 2 | G12: =IF($F12="","",IFERROR(LOOKUP(VALUE(LEFT($F12&"",FIND("-",$F12&"-")-1)),$C$50:$C$56,$D$50:$D$56),"")) -> 750 | H12: 750 | I12: =IF($H12="","n/a",IF($G12=$H12,"ok","MISMATCH")) -> ok | J12: 70000 | M12: Team Liquid
B13: Team Vitality | C13: Pac | D13: 13 | E13: 13 | F13: 3 | G13: =IF($F13="","",IFERROR(LOOKUP(VALUE(LEFT($F13&"",FIND("-",$F13&"-")-1)),$C$50:$C$56,$D$50:$D$56),"")) -> 500 | H13: 500 | I13: =IF($H13="","n/a",IF($G13=$H13,"ok","MISMATCH")) -> ok | J13: 35000 | M13: Team Vitality
B14: Natus Vincere | C14: mime | D14: 12 | E14: 12 | F14: 4 | G14: =IF($F14="","",IFERROR(LOOKUP(VALUE(LEFT($F14&"",FIND("-",$F14&"-")-1)),$C$50:$C$56,$D$50:$D$56),"")) -> 300 | H14: 300 | I14: =IF($H14="","n/a",IF($G14=$H14,"ok","MISMATCH")) -> ok | J14: 25000 | M14: Natus Vincere
B15: Team Nemesis | C15: eLconn21 | D15: 6 | E15: 6 | F15: 5-6 | G15: =IF($F15="","",IFERROR(LOOKUP(VALUE(LEFT($F15&"",FIND("-",$F15&"-")-1)),$C$50:$C$56,$D$50:$D$56),"")) -> 200 | H15: 200 | I15: =IF($H15="","n/a",IF($G15=$H15,"ok","MISMATCH")) -> ok | J15: 20000 | M15: Team Nemesis
B16: BIG | C16: GranaDy | D16: 2 | E16: 2 | F16: 5-6 | G16: =IF($F16="","",IFERROR(LOOKUP(VALUE(LEFT($F16&"",FIND("-",$F16&"-")-1)),$C$50:$C$56,$D$50:$D$56),"")) -> 200 | H16: 200 | I16: =IF($H16="","n/a",IF($G16=$H16,"ok","MISMATCH")) -> ok | J16: 20000 | M16: BIG
B17: Team Liquid | C17: Otaaaq | D17: 10 | E17: 10 | F17: 7-8 | G17: =IF($F17="","",IFERROR(LOOKUP(VALUE(LEFT($F17&"",FIND("-",$F17&"-")-1)),$C$50:$C$56,$D$50:$D$56),"")) -> 100 | I17: =IF($H17="","n/a",IF($G17=$H17,"ok","MISMATCH")) -> n/a | J17: 15000 | K17: Liquid's second entry — best-only rule means it scores nothing | M17: Team Liquid
B18: GodLike Esports | C18: Stufts | D18: 16 | E18: 17 | F18: 7-8 | G18: =IF($F18="","",IFERROR(LOOKUP(VALUE(LEFT($F18&"",FIND("-",$F18&"-")-1)),$C$50:$C$56,$D$50:$D$56),"")) -> 100 | I18: =IF($H18="","n/a",IF($G18=$H18,"ok","MISMATCH")) -> n/a | J18: 15000 | M18: GodLike
B19: AG.AL International | C19: Binkss | D19: 1 | E19: 1 | F19: 9-12 | G19: =IF($F19="","",IFERROR(LOOKUP(VALUE(LEFT($F19&"",FIND("-",$F19&"-")-1)),$C$50:$C$56,$D$50:$D$56),"")) -> 0 | I19: =IF($H19="","n/a",IF($G19=$H19,"ok","MISMATCH")) -> n/a | J19: 12500 | K19: Elite Cup winner; AG.AL second entry | M19: AG.AL International
B20: Team Falcons | C20: Carl Jr. | D20: 8 | E20: 8 | F20: 9-12 | G20: =IF($F20="","",IFERROR(LOOKUP(VALUE(LEFT($F20&"",FIND("-",$F20&"-")-1)),$C$50:$C$56,$D$50:$D$56),"")) -> 0 | H20: 0 | I20: =IF($H20="","n/a",IF($G20=$H20,"ok","MISMATCH")) -> ok | J20: 12500 | M20: Team Falcons
B21: BIG | C21: Massa | D21: 3 | E21: 3 | F21: 9-12 | G21: =IF($F21="","",IFERROR(LOOKUP(VALUE(LEFT($F21&"",FIND("-",$F21&"-")-1)),$C$50:$C$56,$D$50:$D$56),"")) -> 0 | I21: =IF($H21="","n/a",IF($G21=$H21,"ok","MISMATCH")) -> n/a | J21: 12500 | K21: BIG second entry | M21: BIG
B22: VP x Neon | C22: Pusztitopako | D22: 21 | E22: 26 | F22: 9-12 | G22: =IF($F22="","",IFERROR(LOOKUP(VALUE(LEFT($F22&"",FIND("-",$F22&"-")-1)),$C$50:$C$56,$D$50:$D$56),"")) -> 0 | I22: =IF($H22="","n/a",IF($G22=$H22,"ok","MISMATCH")) -> n/a | J22: 12500 | K22: partner brand — points did not accrue to Virtus.pro | M22: VP x Neon
B23: Twisted Minds | C23: Bren | D23: 15 | E23: 16 | F23: 13-16 | G23: =IF($F23="","",IFERROR(LOOKUP(VALUE(LEFT($F23&"",FIND("-",$F23&"-")-1)),$C$50:$C$56,$D$50:$D$56),"")) -> 0 | H23: 0 | I23: =IF($H23="","n/a",IF($G23=$H23,"ok","MISMATCH")) -> ok | J23: 10000 | M23: Twisted Minds
B24: w. | C24: josh1248 | D24: 19 | E24: 20 | F24: 13-16 | G24: =IF($F24="","",IFERROR(LOOKUP(VALUE(LEFT($F24&"",FIND("-",$F24&"-")-1)),$C$50:$C$56,$D$50:$D$56),"")) -> 0 | I24: =IF($H24="","n/a",IF($G24=$H24,"ok","MISMATCH")) -> n/a | J24: 10000 | M24: w.
B25: (no club) | C25: neon | D25: 24 | E25: 44 | F25: 13-16 | G25: =IF($F25="","",IFERROR(LOOKUP(VALUE(LEFT($F25&"",FIND("-",$F25&"-")-1)),$C$50:$C$56,$D$50:$D$56),"")) -> 0 | I25: =IF($H25="","n/a",IF($G25=$H25,"ok","MISMATCH")) -> n/a | J25: 10000 | M25: (no club)
